# Introduction à l'art du test avec pytest 

## Pré-requis
- Vocabulaire : test automatique
- Savoir utiliser pip en ligne de commande

## Objectifs
- Savoir installer pytest
- Savoir écrire un test
- Savoir lancer un test

## Qu'est-ce que pytest ?

Pytest est un framework permettant de mettre en place des tests automatiques dans un projet Python. 
Il est simple à installer et utiliser. Bien qu'il ne soit pas nécessaire de s'en servir dès le départ, pytest propose énormément de fonctionnalité qui permettent d'aller plus loin dans l'art du testing au fur et à mesure que l'on acquiert la maîtrise de celui-ci. 

Dans ce chapitre, tu apprendras à installer pytest et à l'utiliser de manière classique. 

## Installation de pytest

Grâce à la magie de Python et de *pip*, pytest s'installe très facilement.

Vérifions déjà qu'il ne soit pas installé. Dans un terminal, exécute la commande suivante : 
```bash
python -m pytest --version
```

S'il n'est pas installé, tu devrais obtenir le résultat suivant : 
```bash
No module named pytest
```

C'est le cas ? Tu peux donc l'installer. Toujours dans le terminal : 
```bash
python -m pip install pytest
```

Une fois le traitement terminé, on revérifie l'installation : 
```bash
python -m pytest --version
```

Moi, j'obtiens cette ligne qui m'indique que la version *7.0.1* de *pytest* est installée : 
```bash
pytest 7.0.1
```

## Utilisation de pytest

Maintenant que pytest est correctement installé, tu vas pouvoir l'utiliser et écrire ton premier test unitaire. Je t'invite à créer un répertoire `start_with_pytest`. Nous placerons tes premiers tests dedans. Rentre dans ce répertoire en mode terminal et essayons d'exécuter les tests qui se trouvent dedans (pour rappel, il n'y en a pas).

### Un test se lance ou ne se lance pas

Pour lancer les tests, il faut que tu exécutes la commande suivante : 
```bash
python -m pytest
```

et tu obtiens (à peu près) le résultat suivant : 
```bash
====================================== test session starts ======================================
platform win32 -- Python 3.10.0, pytest-7.0.1, pluggy-1.0.0
rootdir: C:\Projets\start_with_pytest
collected 0 items

===================================== no tests ran in 0.01s =====================================
```

Désormais, tu sais ce qu'il se passe quand pytest ne parvient pas à trouver des tests dans le répertoire courant.

Nous allons maintenant mettre en place notre premier test. Je t'invite à créer le fichier `test_something.py` et à mettre le code suivant dedans : 

```python
def test_do_something_useful():
	pass
```
et exécutons de nouveau nos tests (dernier rappel : `python -m pytest`) : 
```bash
====================================== test session starts ======================================
platform win32 -- Python 3.10.0, pytest-7.0.1, pluggy-1.0.0
rootdir: C:\Projets\start_with_pytest
collected 1 item

test_something.py .                                                                        [100%]

======================================= 1 passed in 0.01s =======================================
```

Certaines données changent. Notre fichier test_something.py apparait, avec un indicateur 100%. Cet indicateur indique le pourcentage de test exécutés à ce stade. La ligne en dessous `1 passed in 0.01s` indique le nombre de tests exécutés ainsi que le temps total d'exécution.

Pytest détecte automatiquement les tests, mais il faut appliquer quelques règles. Essayons de comprendre les plus simples.

Modifies le fichier de la manière suivante : 
```python
def do_something_useful():
	pass
```

et exécutes les tests : 
```bash
====================================== test session starts ======================================
platform win32 -- Python 3.10.0, pytest-7.0.1, pluggy-1.0.0
rootdir: C:\Projets\start_with_pytest
collected 0 items

===================================== no tests ran in 0.01s =====================================
```

Tu as enlevé le préfixe `test` du nom de la fonction. Tu peux donc en déduire que pytest se base sur le mot `test` pour déterminer si une fonction est un test. Tu peux essayer de le mettre en suffixe, tu constateras que le test n'est pas reconnu. Une fonction est donc reconnue comme un test si elle est préfixée par `test`.

Maintenant, refais marcher le test puis renomme le fichier `test_something.py` en `something.py`. Même résultat, il faut le préfixe `test` dans le nom du fichier.

Essaye maintenant de le renommer en `something_test.py` : 

```bash
====================================== test session starts ======================================
platform win32 -- Python 3.10.0, pytest-7.0.1, pluggy-1.0.0
rootdir: C:\Projets\start_with_pytest
collected 1 item

something_test.py .                                                                        [100%]

======================================= 1 passed in 0.01s =======================================
```

Le test est détecté. Tu peux donc préfixer ou sufixer le nom de ton fichier pour qu'il soit reconnu comme un fichier de test. Par contre, (je t'invite à essayer), le mot `test` au milieu du nom ne permet pas de détecter le fichier.

### Un test passe ou échoue
Maintenant que nous avons vu les raisons pour lesquelles un test se lance, nous allons voir qu'un test peut passer ou échouer.

Passer signifie que le test exécute un code qui répond à **TOUTES** les *spécifications* attendues par le développeur. Au contraire, un code qui échoue au test ne répond pas à au moins **UNE** spécification.

Par exemple, le test que tu as manipulé (dans les cas où il était lancé) passait parce que son code répondait à toutes les spécifications, c'est à dire aucune. Je n'ai indiqué aucune raison d'échouer, il est donc passé.

Essayons de voir les raisons qui font qu'un test échoue.

#### Echec en raison d'une erreur de compilation, euh... d'exécution

Après avoir vérifié que ton test se lançait correctement, écris donc le code suivant :   

```python
def test_do_something_useful():
	bla bla bla
```

Si tu connais un minimum python, tu comprendras que j'ai marqué n'importe quoi. Python ne peut tout simplement pas comprendre ce code.

Puis exécutes-le : 
```bash
=========================================== test session starts ============================================
platform win32 -- Python 3.10.0, pytest-7.0.1, pluggy-1.0.0
rootdir: C:\Projets\start_with_pytest
collected 0 items / 1 error

================================================== ERRORS ==================================================
____________________________________ ERROR collecting test_something.py ____________________________________
C:\Users\pasde\AppData\Local\Programs\Python\Python310\lib\site-packages\_pytest\python.py:599: in _importtestmodule
    mod = import_path(self.path, mode=importmode, root=self.config.rootpath)
C:\Users\pasde\AppData\Local\Programs\Python\Python310\lib\site-packages\_pytest\pathlib.py:533: in import_path
    importlib.import_module(module_name)
C:\Users\pasde\AppData\Local\Programs\Python\Python310\lib\importlib\__init__.py:126: in import_module
    return _bootstrap._gcd_import(name[level:], package, level)
<frozen importlib._bootstrap>:1050: in _gcd_import
    ???
<frozen importlib._bootstrap>:1027: in _find_and_load
    ???
<frozen importlib._bootstrap>:1006: in _find_and_load_unlocked
    ???
<frozen importlib._bootstrap>:688: in _load_unlocked
    ???
C:\Users\pasde\AppData\Local\Programs\Python\Python310\lib\site-packages\_pytest\assertion\rewrite.py:162: in exec_module
    source_stat, co = _rewrite_test(fn, self.config)
C:\Users\pasde\AppData\Local\Programs\Python\Python310\lib\site-packages\_pytest\assertion\rewrite.py:364: in _rewrite_test
    tree = ast.parse(source, filename=strfn)
C:\Users\pasde\AppData\Local\Programs\Python\Python310\lib\ast.py:50: in parse
    return compile(source, filename, mode, flags,
E     File "C:\Projets\start_with_pytest\test_something.py", line 2
E               bla bla bla
E                   ^^^^^^^
E   SyntaxError: invalid syntax. Perhaps you forgot a comma?
========================================= short test summary info ==========================================
ERROR test_something.py
!!!!!!!!!!!!!!!!!!!!!!!!!!!!!!!!!! Interrupted: 1 error during collection !!!!!!!!!!!!!!!!!!!!!!!!!!!!!!!!!!
============================================= 1 error in 0.80s =============================================
PS C:\Projets\start_with_pytest>
```

Oui, c'est moche, mais voilà ce qu'il se passe quand on écrit n'importe quoi. Le test nous signale une `SyntaxError`. Python est un langage interprété, les erreurs de syntaxe ne sont pas détectées par un compilateur. Elles sont détectées à l'exécution. Petit détail, l'erreur de syntaxe étant présente dans le fichier test, pytest n'a pas pu considérer ce fichier comme contenant des tests. 

Vu que tu n'as écrit qu'une seule ligne, tu sauras réparer facilement cette erreur.

#### Echec en raison d'une exception

L'erreur de syntaxe précédente est gérée par python à l'aide d'une exception. Mais je distingue ici deux types d'exceptions : les erreurs de syntaxe (tu as écrit n'importe quoi) et les autres exceptions (le programme fait n'importe quoi).

Je ne rentrerai pas dans le détail des exceptions en python dans ce chapitre, voici un code qui déclenche une exception : 

```python
def test_do_something_useful():
	raise Exception("some exception")
```

Lors de l'exécution : 

```pytest
=========================================== test session starts ============================================
platform win32 -- Python 3.10.0, pytest-7.0.1, pluggy-1.0.0
rootdir: C:\Projets\start_with_pytest
collected 1 item

test_something.py F                                                                                   [100%]

================================================= FAILURES =================================================
_________________________________________ test_do_something_useful _________________________________________

    def test_do_something_useful():
>       raise Exception("some exception")
E    Exception: some exception

test_something.py:2: Exception
========================================= short test summary info ==========================================
FAILED test_something.py::test_do_something_useful - Exception: some exception
============================================ 1 failed in 0.08s =============================================
```

Contrairement au cas précédent, pytest a réussi à reconnaître le test, il nous donne d'ailleurs beaucoup de détail. Le `F` indique que le premier test du fichier `test_something.py` est en erreur. Si ça n'avait pas été le cas, il y aurait un point (`.`).


Ensuite, il y a un détail pour chaque test en erreur. On y voit une portion du code, la ligne
en erreur et l'exception qui a été déclenchée. Ce détail nous aide à mieux comprendre ce qui n'a pas fonctionné.

#### Echec en raison d'un mauvais comportement

Le troisième type d'echec que l'on rencontre, c'est lorsque le comportement du code n'est pas le bon. C'est d'ailleurs la raison d'être des tests automatiques, détecter un mauvais comportement. C'est aussi la partie la plus dure car il faut arriver à spécifier le comportement d'un code.

Tu verras plus tard, et surtout, tu expérimenteras plus tard comment spécifier ce comportement. Pour le moment, je te propose de découvrir l'outil principal pour vérifier ce comportement. C'est le mot clé `assert`. Ce mot clé est normalement réservé pour ce que l'on appelle la *programmation défensive* (je n'aborderai probablement pas ce sujet, mais je t'invite à le découvrir par toi même), mais le framework de pytest détourne habilement son utilisation pour en faire un outil magique.

Voyons comment l'utiliser avec le code suivant : 
```python
def test_do_something_useful():
	assert "123" == "456"
```

Voici le résultat du test : 
``` pytest
=========================================== test session starts ============================================
platform win32 -- Python 3.10.0, pytest-7.0.1, pluggy-1.0.0
rootdir: C:\Projets\start_with_pytest
collected 1 item

test_something.py F                                                                                   [100%]

================================================= FAILURES =================================================
_________________________________________ test_do_something_useful _________________________________________

    def test_do_something_useful():
>       assert "123" == "456"
E    AssertionError: assert '123' == '456'
E      - 456
E      + 123

test_something.py:2: AssertionError
========================================= short test summary info ==========================================
FAILED test_something.py::test_do_something_useful - AssertionError: assert '123' == '456'
============================================ 1 failed in 0.14s =============================================
```

Comme précédement, nous voyons le test en erreur mais le détail nous donne des informations différentes. Tout d'abord, c'est une exception de type `AssertionError` qui est levée. *Pytest* met en forme cette exception et nous indique la différence. Il est d'ailleurs intelligent car il nous dit qu'il manque la chaîne de caractères `456` dans l'expression et qu'il y a la chaîne de caractère `123` en trop. On peut considérer que `456` est la valeur attendue et `123` la valeur actuelle produite par le code.

Pour corriger l'erreur, il te faudra donc remplacer `123` par `456` puis rexécuter le test. Ce qui te donnerais : 
```pytest
=========================================== test session starts ============================================
platform win32 -- Python 3.10.0, pytest-7.0.1, pluggy-1.0.0
rootdir: C:\Projets\start_with_pytest
collected 1 item

test_something.py .                                                                                   [100%]

============================================ 1 passed in 0.04s =============================================
```

Voilà, tu as vu les trois raisons pour un test d'échouer.

#### Un test qui passe est un test qui a réussi, ou qui a échoué... en tant que test

J'ai une petite manie, héritée de la pratique de TDD, c'est d'être mal à l'aise lorsque j'écris un test qui passe du premier coup. Il faut alors que je fasse tout pour faire échouer ce test. Je te montrerais différentes méthodes dans les chapitres suivants.

Mais un test qui passe ne veut pas dire que le code est juste, il veut tout simplement dire qu'il n'a pas trouvé de spécification devant faire échouer le test. C'est un énorme piège et je préfère te mettre en garde dès maintenant.

Si un test passe, cela peut signifier les choses suivantes : 
- le test est juste et le code est juste
- le test est faux et le code est faux
- le test est faux et le code est juste

Bref, si le test est faux, tu ne sais pas dans quel état est ton code. Et je vais t'achever avec une petite question : comment savoir si mon test est juste ? Il est très simple de créer un test faux, mais on n'est jamais sûr qu'un test est réellement juste.

Cette question, tu pourras y répondre lorsque tu auras assez d'expérience dans l'art du test. Mais je pense qu'il est important que tu l'aies en tête tout au long de cette formation.
